2019-06-19 16:15:26,115 [ERROR]  Experienced exception while trying to serve
Traceback (most recent call last):
  File "d:\python\envs\rasa1.0\lib\site-packages\sanic\app.py", line 1096, in run
    serve(**server_settings)
  File "d:\python\envs\rasa1.0\lib\site-packages\sanic\server.py", line 742, in serve
    trigger_events(before_start, loop)
  File "d:\python\envs\rasa1.0\lib\site-packages\sanic\server.py", line 604, in trigger_events
    loop.run_until_complete(result)
  File "d:\python\envs\rasa1.0\lib\asyncio\base_events.py", line 584, in run_until_complete
    return future.result()
  File "d:\python\envs\rasa1.0\lib\site-packages\rasa\core\run.py", line 191, in load_agent_on_start
    None, endpoints.tracker_store, _broker
  File "d:\python\envs\rasa1.0\lib\site-packages\rasa\core\tracker_store.py", line 48, in find_tracker_store
    domain=domain, host=store.url, event_broker=event_broker, **store.kwargs
  File "d:\python\envs\rasa1.0\lib\site-packages\rasa\core\tracker_store.py", line 323, in __init__
    self.engine = create_engine(engine_url)
  File "d:\python\envs\rasa1.0\lib\site-packages\sqlalchemy\engine\__init__.py", line 435, in create_engine
    return strategy.create(*args, **kwargs)
  File "d:\python\envs\rasa1.0\lib\site-packages\sqlalchemy\engine\strategies.py", line 98, in create
    (cargs, cparams) = dialect.create_connect_args(u)
  File "d:\python\envs\rasa1.0\lib\site-packages\sqlalchemy\dialects\sqlite\pysqlite.py", line 363, in create_connect_args
    " sqlite:////absolute/path/to/file.db" % (url,)
sqlalchemy.exc.ArgumentError: Invalid SQLite URL: sqlite://localhost/rasa.db
Valid SQLite URL forms are:
 sqlite:///:memory: (or, sqlite://)
 sqlite:///relative/path/to/file.db
 sqlite:////absolute/path/to/file.db
2019-06-19 16:16:54,578 [ERROR]  Experienced exception while trying to serve
Traceback (most recent call last):
  File "d:\python\envs\rasa1.0\lib\site-packages\sanic\app.py", line 1096, in run
    serve(**server_settings)
  File "d:\python\envs\rasa1.0\lib\site-packages\sanic\server.py", line 742, in serve
    trigger_events(before_start, loop)
  File "d:\python\envs\rasa1.0\lib\site-packages\sanic\server.py", line 604, in trigger_events
    loop.run_until_complete(result)
  File "d:\python\envs\rasa1.0\lib\asyncio\base_events.py", line 584, in run_until_complete
    return future.result()
  File "d:\python\envs\rasa1.0\lib\site-packages\rasa\core\run.py", line 191, in load_agent_on_start
    None, endpoints.tracker_store, _broker
  File "d:\python\envs\rasa1.0\lib\site-packages\rasa\core\tracker_store.py", line 48, in find_tracker_store
    domain=domain, host=store.url, event_broker=event_broker, **store.kwargs
  File "d:\python\envs\rasa1.0\lib\site-packages\rasa\core\tracker_store.py", line 323, in __init__
    self.engine = create_engine(engine_url)
  File "d:\python\envs\rasa1.0\lib\site-packages\sqlalchemy\engine\__init__.py", line 435, in create_engine
    return strategy.create(*args, **kwargs)
  File "d:\python\envs\rasa1.0\lib\site-packages\sqlalchemy\engine\strategies.py", line 98, in create
    (cargs, cparams) = dialect.create_connect_args(u)
  File "d:\python\envs\rasa1.0\lib\site-packages\sqlalchemy\dialects\sqlite\pysqlite.py", line 363, in create_connect_args
    " sqlite:////absolute/path/to/file.db" % (url,)
sqlalchemy.exc.ArgumentError: Invalid SQLite URL: sqlite://localhost/rasa.db
Valid SQLite URL forms are:
 sqlite:///:memory: (or, sqlite://)
 sqlite:///relative/path/to/file.db
 sqlite:////absolute/path/to/file.db
2019-06-19 16:17:37,603 [ERROR]  Experienced exception while trying to serve
Traceback (most recent call last):
  File "d:\python\envs\rasa1.0\lib\site-packages\sanic\app.py", line 1096, in run
    serve(**server_settings)
  File "d:\python\envs\rasa1.0\lib\site-packages\sanic\server.py", line 742, in serve
    trigger_events(before_start, loop)
  File "d:\python\envs\rasa1.0\lib\site-packages\sanic\server.py", line 604, in trigger_events
    loop.run_until_complete(result)
  File "d:\python\envs\rasa1.0\lib\asyncio\base_events.py", line 584, in run_until_complete
    return future.result()
  File "d:\python\envs\rasa1.0\lib\site-packages\rasa\core\run.py", line 191, in load_agent_on_start
    None, endpoints.tracker_store, _broker
  File "d:\python\envs\rasa1.0\lib\site-packages\rasa\core\tracker_store.py", line 48, in find_tracker_store
    domain=domain, host=store.url, event_broker=event_broker, **store.kwargs
  File "d:\python\envs\rasa1.0\lib\site-packages\rasa\core\tracker_store.py", line 323, in __init__
    self.engine = create_engine(engine_url)
  File "d:\python\envs\rasa1.0\lib\site-packages\sqlalchemy\engine\__init__.py", line 435, in create_engine
    return strategy.create(*args, **kwargs)
  File "d:\python\envs\rasa1.0\lib\site-packages\sqlalchemy\engine\strategies.py", line 87, in create
    dbapi = dialect_cls.dbapi(**dbapi_args)
  File "d:\python\envs\rasa1.0\lib\site-packages\sqlalchemy\dialects\postgresql\psycopg2.py", line 632, in dbapi
    import psycopg2
ModuleNotFoundError: No module named 'psycopg2'
2019-06-19 16:18:37,167 [ERROR]  Experienced exception while trying to serve
Traceback (most recent call last):
  File "d:\python\envs\rasa1.0\lib\site-packages\sanic\app.py", line 1096, in run
    serve(**server_settings)
  File "d:\python\envs\rasa1.0\lib\site-packages\sanic\server.py", line 742, in serve
    trigger_events(before_start, loop)
  File "d:\python\envs\rasa1.0\lib\site-packages\sanic\server.py", line 604, in trigger_events
    loop.run_until_complete(result)
  File "d:\python\envs\rasa1.0\lib\asyncio\base_events.py", line 584, in run_until_complete
    return future.result()
  File "d:\python\envs\rasa1.0\lib\site-packages\rasa\core\run.py", line 191, in load_agent_on_start
    None, endpoints.tracker_store, _broker
  File "d:\python\envs\rasa1.0\lib\site-packages\rasa\core\tracker_store.py", line 48, in find_tracker_store
    domain=domain, host=store.url, event_broker=event_broker, **store.kwargs
  File "d:\python\envs\rasa1.0\lib\site-packages\rasa\core\tracker_store.py", line 323, in __init__
    self.engine = create_engine(engine_url)
  File "d:\python\envs\rasa1.0\lib\site-packages\sqlalchemy\engine\__init__.py", line 435, in create_engine
    return strategy.create(*args, **kwargs)
  File "d:\python\envs\rasa1.0\lib\site-packages\sqlalchemy\engine\strategies.py", line 98, in create
    (cargs, cparams) = dialect.create_connect_args(u)
  File "d:\python\envs\rasa1.0\lib\site-packages\sqlalchemy\dialects\sqlite\pysqlite.py", line 363, in create_connect_args
    " sqlite:////absolute/path/to/file.db" % (url,)
sqlalchemy.exc.ArgumentError: Invalid SQLite URL: sqlite://localhost/rasa.db
Valid SQLite URL forms are:
 sqlite:///:memory: (or, sqlite://)
 sqlite:///relative/path/to/file.db
 sqlite:////absolute/path/to/file.db
2019-06-19 16:29:54,255 [ERROR]  Experienced exception while trying to serve
Traceback (most recent call last):
  File "d:\python\envs\rasa1.0\lib\site-packages\sanic\app.py", line 1096, in run
    serve(**server_settings)
  File "d:\python\envs\rasa1.0\lib\site-packages\sanic\server.py", line 742, in serve
    trigger_events(before_start, loop)
  File "d:\python\envs\rasa1.0\lib\site-packages\sanic\server.py", line 604, in trigger_events
    loop.run_until_complete(result)
  File "d:\python\envs\rasa1.0\lib\asyncio\base_events.py", line 584, in run_until_complete
    return future.result()
  File "d:\python\envs\rasa1.0\lib\site-packages\rasa\core\run.py", line 191, in load_agent_on_start
    None, endpoints.tracker_store, _broker
  File "d:\python\envs\rasa1.0\lib\site-packages\rasa\core\tracker_store.py", line 48, in find_tracker_store
    domain=domain, host=store.url, event_broker=event_broker, **store.kwargs
  File "d:\python\envs\rasa1.0\lib\site-packages\rasa\core\tracker_store.py", line 323, in __init__
    self.engine = create_engine(engine_url)
  File "d:\python\envs\rasa1.0\lib\site-packages\sqlalchemy\engine\__init__.py", line 435, in create_engine
    return strategy.create(*args, **kwargs)
  File "d:\python\envs\rasa1.0\lib\site-packages\sqlalchemy\engine\strategies.py", line 98, in create
    (cargs, cparams) = dialect.create_connect_args(u)
  File "d:\python\envs\rasa1.0\lib\site-packages\sqlalchemy\dialects\sqlite\pysqlite.py", line 363, in create_connect_args
    " sqlite:////absolute/path/to/file.db" % (url,)
sqlalchemy.exc.ArgumentError: Invalid SQLite URL: sqlite://sqlite/rasa.db
Valid SQLite URL forms are:
 sqlite:///:memory: (or, sqlite://)
 sqlite:///relative/path/to/file.db
 sqlite:////absolute/path/to/file.db
2019-06-19 16:30:40,363 [ERROR]  Experienced exception while trying to serve
Traceback (most recent call last):
  File "d:\python\envs\rasa1.0\lib\site-packages\sanic\app.py", line 1096, in run
    serve(**server_settings)
  File "d:\python\envs\rasa1.0\lib\site-packages\sanic\server.py", line 742, in serve
    trigger_events(before_start, loop)
  File "d:\python\envs\rasa1.0\lib\site-packages\sanic\server.py", line 604, in trigger_events
    loop.run_until_complete(result)
  File "d:\python\envs\rasa1.0\lib\asyncio\base_events.py", line 584, in run_until_complete
    return future.result()
  File "d:\python\envs\rasa1.0\lib\site-packages\rasa\core\run.py", line 191, in load_agent_on_start
    None, endpoints.tracker_store, _broker
  File "d:\python\envs\rasa1.0\lib\site-packages\rasa\core\tracker_store.py", line 48, in find_tracker_store
    domain=domain, host=store.url, event_broker=event_broker, **store.kwargs
  File "d:\python\envs\rasa1.0\lib\site-packages\rasa\core\tracker_store.py", line 323, in __init__
    self.engine = create_engine(engine_url)
  File "d:\python\envs\rasa1.0\lib\site-packages\sqlalchemy\engine\__init__.py", line 435, in create_engine
    return strategy.create(*args, **kwargs)
  File "d:\python\envs\rasa1.0\lib\site-packages\sqlalchemy\engine\strategies.py", line 98, in create
    (cargs, cparams) = dialect.create_connect_args(u)
  File "d:\python\envs\rasa1.0\lib\site-packages\sqlalchemy\dialects\sqlite\pysqlite.py", line 363, in create_connect_args
    " sqlite:////absolute/path/to/file.db" % (url,)
sqlalchemy.exc.ArgumentError: Invalid SQLite URL: sqlite://sqlite/rasa
Valid SQLite URL forms are:
 sqlite:///:memory: (or, sqlite://)
 sqlite:///relative/path/to/file.db
 sqlite:////absolute/path/to/file.db
2019-06-19 16:34:35,669 [ERROR]  Experienced exception while trying to serve
Traceback (most recent call last):
  File "d:\python\envs\rasa1.0\lib\site-packages\sanic\app.py", line 1096, in run
    serve(**server_settings)
  File "d:\python\envs\rasa1.0\lib\site-packages\sanic\server.py", line 742, in serve
    trigger_events(before_start, loop)
  File "d:\python\envs\rasa1.0\lib\site-packages\sanic\server.py", line 604, in trigger_events
    loop.run_until_complete(result)
  File "d:\python\envs\rasa1.0\lib\asyncio\base_events.py", line 584, in run_until_complete
    return future.result()
  File "d:\python\envs\rasa1.0\lib\site-packages\rasa\core\run.py", line 191, in load_agent_on_start
    None, endpoints.tracker_store, _broker
  File "d:\python\envs\rasa1.0\lib\site-packages\rasa\core\tracker_store.py", line 48, in find_tracker_store
    domain=domain, host=store.url, event_broker=event_broker, **store.kwargs
  File "d:\python\envs\rasa1.0\lib\site-packages\rasa\core\tracker_store.py", line 323, in __init__
    self.engine = create_engine(engine_url)
  File "d:\python\envs\rasa1.0\lib\site-packages\sqlalchemy\engine\__init__.py", line 435, in create_engine
    return strategy.create(*args, **kwargs)
  File "d:\python\envs\rasa1.0\lib\site-packages\sqlalchemy\engine\strategies.py", line 98, in create
    (cargs, cparams) = dialect.create_connect_args(u)
  File "d:\python\envs\rasa1.0\lib\site-packages\sqlalchemy\dialects\sqlite\pysqlite.py", line 363, in create_connect_args
    " sqlite:////absolute/path/to/file.db" % (url,)
sqlalchemy.exc.ArgumentError: Invalid SQLite URL: sqlite://localhost
Valid SQLite URL forms are:
 sqlite:///:memory: (or, sqlite://)
 sqlite:///relative/path/to/file.db
 sqlite:////absolute/path/to/file.db
2019-06-19 16:37:46,930 [ERROR]  Experienced exception while trying to serve
Traceback (most recent call last):
  File "d:\python\envs\rasa1.0\lib\site-packages\sanic\app.py", line 1096, in run
    serve(**server_settings)
  File "d:\python\envs\rasa1.0\lib\site-packages\sanic\server.py", line 770, in serve
    loop.run_forever()
  File "d:\python\envs\rasa1.0\lib\asyncio\base_events.py", line 539, in run_forever
    self._run_once()
  File "d:\python\envs\rasa1.0\lib\asyncio\base_events.py", line 1739, in _run_once
    event_list = self._selector.select(timeout)
  File "d:\python\envs\rasa1.0\lib\selectors.py", line 323, in select
    r, w, _ = self._select(self._readers, self._writers, [], timeout)
  File "d:\python\envs\rasa1.0\lib\selectors.py", line 314, in _select
    r, w, x = select.select(r, w, w, timeout)
  File "d:\python\envs\rasa1.0\lib\site-packages\engineio\client.py", line 41, in signal_handler
    return original_signal_handler(sig, frame)
KeyboardInterrupt
2019-06-19 16:40:28,587 [ERROR]  Exception occurred while handling uri: 'http://localhost:5005/'
Traceback (most recent call last):
  File "d:\python\envs\rasa1.0\lib\site-packages\sanic\app.py", line 893, in handle_request
    handler, args, kwargs, uri = self.router.get(request)
  File "d:\python\envs\rasa1.0\lib\site-packages\sanic\router.py", line 407, in get
    return self._get(request.path, request.method, "")
  File "d:\python\envs\rasa1.0\lib\site-packages\sanic\router.py", line 469, in _get
    raise NotFound("Requested URL {} not found".format(url))
sanic.exceptions.NotFound: Requested URL / not found
2019-06-19 16:40:29,127 [ERROR]  Exception occurred while handling uri: 'http://localhost:5005/favicon.ico'
Traceback (most recent call last):
  File "d:\python\envs\rasa1.0\lib\site-packages\sanic\app.py", line 893, in handle_request
    handler, args, kwargs, uri = self.router.get(request)
  File "d:\python\envs\rasa1.0\lib\site-packages\sanic\router.py", line 407, in get
    return self._get(request.path, request.method, "")
  File "d:\python\envs\rasa1.0\lib\site-packages\sanic\router.py", line 469, in _get
    raise NotFound("Requested URL {} not found".format(url))
sanic.exceptions.NotFound: Requested URL /favicon.ico not found
2019-06-19 16:41:28,615 [ERROR]  Exception occurred while handling uri: unknown
NoneType: None
2019-06-19 16:41:28,829 [ERROR]  Exception occurred while handling uri: unknown
NoneType: None
