No valid configuration given to load agent.
Agent could not be loaded with the provided configuration.Load default agent without any model.
exception calling callback for <Future at 0x2398c0428d0 state=finished returned list>
Traceback (most recent call last):
  File "d:\python\envs\rasa1.0\lib\concurrent\futures\_base.py", line 324, in _invoke_callbacks
    callback(self)
  File "d:\python\envs\rasa1.0\lib\asyncio\futures.py", line 362, in _call_set_state
    dest_loop.call_soon_threadsafe(_set_state, destination, source)
  File "d:\python\envs\rasa1.0\lib\asyncio\base_events.py", line 733, in call_soon_threadsafe
    self._check_closed()
  File "d:\python\envs\rasa1.0\lib\asyncio\base_events.py", line 480, in _check_closed
    raise RuntimeError('Event loop is closed')
RuntimeError: Event loop is closed
Task was destroyed but it is pending!
task: <Task pending coro=<TCPConnector._resolve_host() done, defined at d:\python\envs\rasa1.0\lib\site-packages\aiohttp\connector.py:773> wait_for=<Future pending cb=[_chain_future.<locals>._call_check_cancel() at d:\python\envs\rasa1.0\lib\asyncio\futures.py:348, <TaskWakeupMethWrapper object at 0x000002398BFDCCA8>()]> cb=[shield.<locals>._done_callback() at d:\python\envs\rasa1.0\lib\asyncio\tasks.py:776]>
